04-Mar-22 17:18:41 - Exception occurred
Traceback (most recent call last):
  File "/Users/simplypatrickg/.local/lib/python3.8/site-packages/pandas/io/sql.py", line 1595, in execute
    cur.execute(*args)
  File "/Users/simplypatrickg/.local/lib/python3.8/site-packages/mysql/connector/cursor.py", line 568, in execute
    self._handle_result(self._connection.cmd_query(stmt))
  File "/Users/simplypatrickg/.local/lib/python3.8/site-packages/mysql/connector/connection.py", line 846, in cmd_query
    result = self._handle_result(self._send_cmd(ServerCmd.QUERY, query))
  File "/Users/simplypatrickg/.local/lib/python3.8/site-packages/mysql/connector/connection.py", line 656, in _handle_result
    raise errors.get_exception(packet)
mysql.connector.errors.ProgrammingError: 1064 (42000): You have an error in your SQL syntax; check the manual that corresponds to your MySQL server version for the right syntax to use near ''' at line 1

During handling of the above exception, another exception occurred:

Traceback (most recent call last):
  File "/tmp/ipykernel_23205/2466134560.py", line 15, in <module>
    marketpredict = pd.read_sql(query, conn)
  File "/Users/simplypatrickg/.local/lib/python3.8/site-packages/pandas/io/sql.py", line 404, in read_sql
    return pandas_sql.read_query(
  File "/Users/simplypatrickg/.local/lib/python3.8/site-packages/pandas/io/sql.py", line 1645, in read_query
    cursor = self.execute(*args)
  File "/Users/simplypatrickg/.local/lib/python3.8/site-packages/pandas/io/sql.py", line 1610, in execute
    raise_with_traceback(ex)
  File "/Users/simplypatrickg/.local/lib/python3.8/site-packages/pandas/compat/__init__.py", line 47, in raise_with_traceback
    raise exc.with_traceback(traceback)
  File "/Users/simplypatrickg/.local/lib/python3.8/site-packages/pandas/io/sql.py", line 1595, in execute
    cur.execute(*args)
  File "/Users/simplypatrickg/.local/lib/python3.8/site-packages/mysql/connector/cursor.py", line 568, in execute
    self._handle_result(self._connection.cmd_query(stmt))
  File "/Users/simplypatrickg/.local/lib/python3.8/site-packages/mysql/connector/connection.py", line 846, in cmd_query
    result = self._handle_result(self._send_cmd(ServerCmd.QUERY, query))
  File "/Users/simplypatrickg/.local/lib/python3.8/site-packages/mysql/connector/connection.py", line 656, in _handle_result
    raise errors.get_exception(packet)
pandas.io.sql.DatabaseError: Execution failed on sql 'SELECT*';': 1064 (42000): You have an error in your SQL syntax; check the manual that corresponds to your MySQL server version for the right syntax to use near ''' at line 1
04-Mar-22 17:18:50 - Exception occurred
Traceback (most recent call last):
  File "/Users/simplypatrickg/.local/lib/python3.8/site-packages/pandas/io/sql.py", line 1595, in execute
    cur.execute(*args)
  File "/Users/simplypatrickg/.local/lib/python3.8/site-packages/mysql/connector/cursor.py", line 568, in execute
    self._handle_result(self._connection.cmd_query(stmt))
  File "/Users/simplypatrickg/.local/lib/python3.8/site-packages/mysql/connector/connection.py", line 846, in cmd_query
    result = self._handle_result(self._send_cmd(ServerCmd.QUERY, query))
  File "/Users/simplypatrickg/.local/lib/python3.8/site-packages/mysql/connector/connection.py", line 656, in _handle_result
    raise errors.get_exception(packet)
mysql.connector.errors.ProgrammingError: 1064 (42000): You have an error in your SQL syntax; check the manual that corresponds to your MySQL server version for the right syntax to use near ''' at line 1

During handling of the above exception, another exception occurred:

Traceback (most recent call last):
  File "/tmp/ipykernel_23205/2466134560.py", line 15, in <module>
    marketpredict = pd.read_sql(query, conn)
  File "/Users/simplypatrickg/.local/lib/python3.8/site-packages/pandas/io/sql.py", line 404, in read_sql
    return pandas_sql.read_query(
  File "/Users/simplypatrickg/.local/lib/python3.8/site-packages/pandas/io/sql.py", line 1645, in read_query
    cursor = self.execute(*args)
  File "/Users/simplypatrickg/.local/lib/python3.8/site-packages/pandas/io/sql.py", line 1610, in execute
    raise_with_traceback(ex)
  File "/Users/simplypatrickg/.local/lib/python3.8/site-packages/pandas/compat/__init__.py", line 47, in raise_with_traceback
    raise exc.with_traceback(traceback)
  File "/Users/simplypatrickg/.local/lib/python3.8/site-packages/pandas/io/sql.py", line 1595, in execute
    cur.execute(*args)
  File "/Users/simplypatrickg/.local/lib/python3.8/site-packages/mysql/connector/cursor.py", line 568, in execute
    self._handle_result(self._connection.cmd_query(stmt))
  File "/Users/simplypatrickg/.local/lib/python3.8/site-packages/mysql/connector/connection.py", line 846, in cmd_query
    result = self._handle_result(self._send_cmd(ServerCmd.QUERY, query))
  File "/Users/simplypatrickg/.local/lib/python3.8/site-packages/mysql/connector/connection.py", line 656, in _handle_result
    raise errors.get_exception(packet)
pandas.io.sql.DatabaseError: Execution failed on sql 'SELECT*';': 1064 (42000): You have an error in your SQL syntax; check the manual that corresponds to your MySQL server version for the right syntax to use near ''' at line 1
04-Mar-22 17:19:26 - Exception occurred
Traceback (most recent call last):
  File "/Users/simplypatrickg/.local/lib/python3.8/site-packages/pandas/io/sql.py", line 1595, in execute
    cur.execute(*args)
  File "/Users/simplypatrickg/.local/lib/python3.8/site-packages/mysql/connector/cursor.py", line 568, in execute
    self._handle_result(self._connection.cmd_query(stmt))
  File "/Users/simplypatrickg/.local/lib/python3.8/site-packages/mysql/connector/connection.py", line 846, in cmd_query
    result = self._handle_result(self._send_cmd(ServerCmd.QUERY, query))
  File "/Users/simplypatrickg/.local/lib/python3.8/site-packages/mysql/connector/connection.py", line 656, in _handle_result
    raise errors.get_exception(packet)
mysql.connector.errors.ProgrammingError: 1064 (42000): You have an error in your SQL syntax; check the manual that corresponds to your MySQL server version for the right syntax to use near ''' at line 1

During handling of the above exception, another exception occurred:

Traceback (most recent call last):
  File "/tmp/ipykernel_23205/474105959.py", line 15, in <module>
    marketpredict = pd.read_sql(query, conn)
  File "/Users/simplypatrickg/.local/lib/python3.8/site-packages/pandas/io/sql.py", line 404, in read_sql
    return pandas_sql.read_query(
  File "/Users/simplypatrickg/.local/lib/python3.8/site-packages/pandas/io/sql.py", line 1645, in read_query
    cursor = self.execute(*args)
  File "/Users/simplypatrickg/.local/lib/python3.8/site-packages/pandas/io/sql.py", line 1610, in execute
    raise_with_traceback(ex)
  File "/Users/simplypatrickg/.local/lib/python3.8/site-packages/pandas/compat/__init__.py", line 47, in raise_with_traceback
    raise exc.with_traceback(traceback)
  File "/Users/simplypatrickg/.local/lib/python3.8/site-packages/pandas/io/sql.py", line 1595, in execute
    cur.execute(*args)
  File "/Users/simplypatrickg/.local/lib/python3.8/site-packages/mysql/connector/cursor.py", line 568, in execute
    self._handle_result(self._connection.cmd_query(stmt))
  File "/Users/simplypatrickg/.local/lib/python3.8/site-packages/mysql/connector/connection.py", line 846, in cmd_query
    result = self._handle_result(self._send_cmd(ServerCmd.QUERY, query))
  File "/Users/simplypatrickg/.local/lib/python3.8/site-packages/mysql/connector/connection.py", line 656, in _handle_result
    raise errors.get_exception(packet)
pandas.io.sql.DatabaseError: Execution failed on sql 'SELECT * FROM DailyOutputs';': 1064 (42000): You have an error in your SQL syntax; check the manual that corresponds to your MySQL server version for the right syntax to use near ''' at line 1
04-Mar-22 17:19:53 - Exception occurred
Traceback (most recent call last):
  File "/Users/simplypatrickg/.local/lib/python3.8/site-packages/pandas/io/sql.py", line 1595, in execute
    cur.execute(*args)
  File "/Users/simplypatrickg/.local/lib/python3.8/site-packages/mysql/connector/cursor.py", line 568, in execute
    self._handle_result(self._connection.cmd_query(stmt))
  File "/Users/simplypatrickg/.local/lib/python3.8/site-packages/mysql/connector/connection.py", line 846, in cmd_query
    result = self._handle_result(self._send_cmd(ServerCmd.QUERY, query))
  File "/Users/simplypatrickg/.local/lib/python3.8/site-packages/mysql/connector/connection.py", line 656, in _handle_result
    raise errors.get_exception(packet)
mysql.connector.errors.ProgrammingError: 1064 (42000): You have an error in your SQL syntax; check the manual that corresponds to your MySQL server version for the right syntax to use near ''' at line 1

During handling of the above exception, another exception occurred:

Traceback (most recent call last):
  File "/tmp/ipykernel_23205/474105959.py", line 15, in <module>
    marketpredict = pd.read_sql(query, conn)
  File "/Users/simplypatrickg/.local/lib/python3.8/site-packages/pandas/io/sql.py", line 404, in read_sql
    return pandas_sql.read_query(
  File "/Users/simplypatrickg/.local/lib/python3.8/site-packages/pandas/io/sql.py", line 1645, in read_query
    cursor = self.execute(*args)
  File "/Users/simplypatrickg/.local/lib/python3.8/site-packages/pandas/io/sql.py", line 1610, in execute
    raise_with_traceback(ex)
  File "/Users/simplypatrickg/.local/lib/python3.8/site-packages/pandas/compat/__init__.py", line 47, in raise_with_traceback
    raise exc.with_traceback(traceback)
  File "/Users/simplypatrickg/.local/lib/python3.8/site-packages/pandas/io/sql.py", line 1595, in execute
    cur.execute(*args)
  File "/Users/simplypatrickg/.local/lib/python3.8/site-packages/mysql/connector/cursor.py", line 568, in execute
    self._handle_result(self._connection.cmd_query(stmt))
  File "/Users/simplypatrickg/.local/lib/python3.8/site-packages/mysql/connector/connection.py", line 846, in cmd_query
    result = self._handle_result(self._send_cmd(ServerCmd.QUERY, query))
  File "/Users/simplypatrickg/.local/lib/python3.8/site-packages/mysql/connector/connection.py", line 656, in _handle_result
    raise errors.get_exception(packet)
pandas.io.sql.DatabaseError: Execution failed on sql 'SELECT * FROM DailyOutputs';': 1064 (42000): You have an error in your SQL syntax; check the manual that corresponds to your MySQL server version for the right syntax to use near ''' at line 1
04-Mar-22 17:20:44 - Exception occurred
Traceback (most recent call last):
  File "/Users/simplypatrickg/.local/lib/python3.8/site-packages/pandas/io/sql.py", line 1595, in execute
    cur.execute(*args)
  File "/Users/simplypatrickg/.local/lib/python3.8/site-packages/mysql/connector/cursor.py", line 568, in execute
    self._handle_result(self._connection.cmd_query(stmt))
  File "/Users/simplypatrickg/.local/lib/python3.8/site-packages/mysql/connector/connection.py", line 846, in cmd_query
    result = self._handle_result(self._send_cmd(ServerCmd.QUERY, query))
  File "/Users/simplypatrickg/.local/lib/python3.8/site-packages/mysql/connector/connection.py", line 656, in _handle_result
    raise errors.get_exception(packet)
mysql.connector.errors.ProgrammingError: 1064 (42000): You have an error in your SQL syntax; check the manual that corresponds to your MySQL server version for the right syntax to use near ''' at line 1

During handling of the above exception, another exception occurred:

Traceback (most recent call last):
  File "/tmp/ipykernel_23205/3005204417.py", line 15, in <module>
    marketpredict = pd.read_sql(query, conn)
  File "/Users/simplypatrickg/.local/lib/python3.8/site-packages/pandas/io/sql.py", line 404, in read_sql
    return pandas_sql.read_query(
  File "/Users/simplypatrickg/.local/lib/python3.8/site-packages/pandas/io/sql.py", line 1645, in read_query
    cursor = self.execute(*args)
  File "/Users/simplypatrickg/.local/lib/python3.8/site-packages/pandas/io/sql.py", line 1610, in execute
    raise_with_traceback(ex)
  File "/Users/simplypatrickg/.local/lib/python3.8/site-packages/pandas/compat/__init__.py", line 47, in raise_with_traceback
    raise exc.with_traceback(traceback)
  File "/Users/simplypatrickg/.local/lib/python3.8/site-packages/pandas/io/sql.py", line 1595, in execute
    cur.execute(*args)
  File "/Users/simplypatrickg/.local/lib/python3.8/site-packages/mysql/connector/cursor.py", line 568, in execute
    self._handle_result(self._connection.cmd_query(stmt))
  File "/Users/simplypatrickg/.local/lib/python3.8/site-packages/mysql/connector/connection.py", line 846, in cmd_query
    result = self._handle_result(self._send_cmd(ServerCmd.QUERY, query))
  File "/Users/simplypatrickg/.local/lib/python3.8/site-packages/mysql/connector/connection.py", line 656, in _handle_result
    raise errors.get_exception(packet)
pandas.io.sql.DatabaseError: Execution failed on sql 'SELECT Date FROM DailyOutputs';': 1064 (42000): You have an error in your SQL syntax; check the manual that corresponds to your MySQL server version for the right syntax to use near ''' at line 1
